Traceback (most recent call last):
  File "c:\users\hanlu\anaconda3\lib\site-packages\jupyter_cache\executors\utils.py", line 56, in single_nb_execution
    record_timing=False,
  File "c:\users\hanlu\anaconda3\lib\site-packages\nbclient\client.py", line 1087, in execute
    return NotebookClient(nb=nb, resources=resources, km=km, **kwargs).execute()
  File "c:\users\hanlu\anaconda3\lib\site-packages\nbclient\util.py", line 74, in wrapped
    return just_run(coro(*args, **kwargs))
  File "c:\users\hanlu\anaconda3\lib\site-packages\nbclient\util.py", line 53, in just_run
    return loop.run_until_complete(coro)
  File "c:\users\hanlu\anaconda3\lib\asyncio\base_events.py", line 583, in run_until_complete
    return future.result()
  File "c:\users\hanlu\anaconda3\lib\site-packages\nbclient\client.py", line 541, in async_execute
    cell, index, execution_count=self.code_cells_executed + 1
  File "c:\users\hanlu\anaconda3\lib\site-packages\nbclient\client.py", line 832, in async_execute_cell
    self._check_raise_for_error(cell, exec_reply)
  File "c:\users\hanlu\anaconda3\lib\site-packages\nbclient\client.py", line 740, in _check_raise_for_error
    raise CellExecutionError.from_cell_and_msg(cell, exec_reply['content'])
nbclient.exceptions.CellExecutionError: An error occurred while executing the following cell:
------------------
import warnings
warnings.filterwarnings('ignore')
# Filter business_id according to the category
filter_business_id = business_df[business_df.categories.str.contains(r"(Hotels, )|(, Hotels$)", regex = True)==True].business_id
# Filter businesses
business_df = business_df[business_df.business_id.isin(filter_business_id)].reset_index().drop('index', axis = 1).rename({'stars': 'stars_business'})
# Filter reviews based on business_id
review_df = review_df[review_df.business_id.isin(filter_business_id)].reset_index().drop('index', axis = 1).rename({'stars': 'stars_review'})

#columns = ['business_id', 'name', 'address', 'city', 'state', 'postal_code',
       #'latitude', 'longitude', 'stars', 'review_count', 'is_open',
       #'attributes', 'categories', 'hours']
#@interact
#def show_dataframe(column1=columns, column2 = columns, column3 = columns, column4 = columns):
    
    #return business_df[[column1]+[column2]+[column3]+[column4]]

business_df
------------------

[1;31m---------------------------------------------------------------------------[0m
[1;31mNameError[0m                                 Traceback (most recent call last)
[1;32m<ipython-input-2-491a7e15ea15>[0m in [0;36m<module>[1;34m[0m
[0;32m      2[0m [0mwarnings[0m[1;33m.[0m[0mfilterwarnings[0m[1;33m([0m[1;34m'ignore'[0m[1;33m)[0m[1;33m[0m[1;33m[0m[0m
[0;32m      3[0m [1;31m# Filter business_id according to the category[0m[1;33m[0m[1;33m[0m[1;33m[0m[0m
[1;32m----> 4[1;33m [0mfilter_business_id[0m [1;33m=[0m [0mbusiness_df[0m[1;33m[[0m[0mbusiness_df[0m[1;33m.[0m[0mcategories[0m[1;33m.[0m[0mstr[0m[1;33m.[0m[0mcontains[0m[1;33m([0m[1;34mr"(Hotels, )|(, Hotels$)"[0m[1;33m,[0m [0mregex[0m [1;33m=[0m [1;32mTrue[0m[1;33m)[0m[1;33m==[0m[1;32mTrue[0m[1;33m][0m[1;33m.[0m[0mbusiness_id[0m[1;33m[0m[1;33m[0m[0m
[0m[0;32m      5[0m [1;31m# Filter businesses[0m[1;33m[0m[1;33m[0m[1;33m[0m[0m
[0;32m      6[0m [0mbusiness_df[0m [1;33m=[0m [0mbusiness_df[0m[1;33m[[0m[0mbusiness_df[0m[1;33m.[0m[0mbusiness_id[0m[1;33m.[0m[0misin[0m[1;33m([0m[0mfilter_business_id[0m[1;33m)[0m[1;33m][0m[1;33m.[0m[0mreset_index[0m[1;33m([0m[1;33m)[0m[1;33m.[0m[0mdrop[0m[1;33m([0m[1;34m'index'[0m[1;33m,[0m [0maxis[0m [1;33m=[0m [1;36m1[0m[1;33m)[0m[1;33m.[0m[0mrename[0m[1;33m([0m[1;33m{[0m[1;34m'stars'[0m[1;33m:[0m [1;34m'stars_business'[0m[1;33m}[0m[1;33m)[0m[1;33m[0m[1;33m[0m[0m

[1;31mNameError[0m: name 'business_df' is not defined
NameError: name 'business_df' is not defined

